 
 2022-01-24 14:24:19,692 -  Invalid value entered at  Email -ID  = vishwa@gmail
 
 2022-01-24 14:43:14,997 - editor error
Traceback (most recent call last):
  File "D:\bridgelabz\python\address_book\services\contact_operations.py", line 82, in editor
    AddressBooks.system_registry.pop(contact_object)
KeyError: <registry.address_book.AddressBooks object at 0x000002B1ACF87B50>
 
 2022-01-24 17:15:36,506 -  Invalid value entered at  Last Name  = itis
 
 2022-01-24 17:16:06,331 -  Invalid value entered at  Email -ID  = Vishw@gmai
 
 2022-01-24 18:15:48,611 -  Invalid value entered at  Zip code  = 58001
 
 2022-01-24 18:16:55,483 -  Invalid value entered at  First Name  = 
 
 2022-01-24 19:37:19,785 -  Invalid value entered at  Last Name  = Iti
 
 2022-01-24 19:37:50,665 - Error at menu operations, choice is 5
Traceback (most recent call last):
  File "D:\bridgelabz\python\address_book\services\operations.py", line 88, in menu
    Operations().search_dict(choice)
  File "D:\bridgelabz\python\address_book\services\operations.py", line 193, in search_dict
    self.search_function(searcher.get(choice).index(0), searcher.get(choice).index(1))
ValueError: tuple.index(x): x not in tuple
 
 2022-01-24 20:02:36,475 - error
Traceback (most recent call last):
  File "D:\bridgelabz\python\address_book\services\operations.py", line 38, in get_user_choice
    option = int(input("Press \n 1) Add new Address Book \n 2) Edit Existing book "
ValueError: invalid literal for int() with base 10: 'Vishwanath'
